Workbook

Sheet Change List
B2: SL no | C2: Date | D2: Description | E2: Name
B3: 1 | C3: 14.11.2024 | D3: - Learning done with first chamber trial - Sin and Cos nominal value updated - T30 nominal value and formulas updated | E3: Renuka Prasanna
B4: 2 | C4: 19.11.2024 | D4: Updated Sine, Cos, Temp Inv, T30 and proximity limits for all the modes | E4: Renuka Prasanna
B5: 3 | C5: 25.11.2024 | D5: Updating Mean values after learning for Hight Temperature Test | E5: Abhay Kumar

Sheet FE_FF_Frame_Limit_V4
A1: ID | B1: SIGNAL_NAME | C1: COMPARISON_TYPE | D1: ERROR_MESSSAGE | E1: SEVERITY | F1: COMPARISON_ENABLE | G1: MODE1_NOMINAL | H1: MODE1_MIN | I1: MODE1_MAX | J1: MODE2_NOMINAL | K1: MODE2_MIN | L1: MODE2_MAX | M1: MODE3_NOMINAL | N1: MODE3_MIN | O1: MODE3_MAX | P1: MODE4_NOMINAL | Q1: MODE4_MIN | R1: MODE4_MAX | S1: MODE5_NOMINAL | T1: MODE5_MIN | U1: MODE5_MAX | V1: MODE6_NOMINAL | W1: MODE6_MIN | X1: MODE6_MAX | Y1: MODE7_NOMINAL | Z1: MODE7_MIN | AA1: MODE7_MAX | AB1: MODE8_NOMINAL | AC1: MODE8_MIN | AD1: MODE8_MAX | AE1: MODE9_NOMINAL | AF1: MODE9_MIN | AG1: MODE9_MAX | AH1: MODE10_NOMINAL | AI1: MODE10_MIN | AJ1: MODE10_MAX | AK1: MODE11_NOMINAL | AL1: MODE11_MIN | AM1: MODE11_MAX | AN1: MODE12_NOMINAL | AO1: MODE12_MIN | AP1: MODE12_MAX | AQ1: MODE13_NOMINAL | AR1: MODE13_MIN | AS1: MODE13_MAX | AT1: MODE14_NOMINAL | AU1: MODE14_MIN | AV1: MODE14_MAX | AW1: MODE15_NOMINAL | AX1: MODE15_MIN | AY1: MODE15_MAX | AZ1: MODE16_NOMINAL | BA1: MODE16_MIN | BB1: MODE16_MAX | BC1: MODE17_NOMINAL | BD1: MODE17_MIN | BE1: MODE17_MAX
A2: 1 | B2: COM_STATUS | C2: EQ | F2: 1 | G2: 160 | J2: 160 | M2: 160 | P2: 160 | S2: 160 | V2: 160 | Y2: 160 | AB2: 160 | AE2: 160 | AH2: 160 | AK2: 160
A3: 2 | B3: CYT2B9_STATUS | C3: EQ | F3: 1 | G3: 160 | J3: 160 | M3: 160 | P3: 160 | S3: 160 | V3: 160 | Y3: 160 | AB3: 160 | AE3: 160 | AH3: 160 | AK3: 160
A4: 3 | B4: RST_CNT_UNKNOWN | C4: EQ | F4: 1 | G4: 0 | J4: 0 | M4: 0 | P4: 0 | S4: 0 | V4: 0 | Y4: 0 | AB4: 0 | AE4: 0 | AH4: 0 | AK4: 0
A5: 4 | B5: RST_CNT_PORST | C5: EQ | F5: 1 | G5: 0 | J5: 0 | M5: 0 | P5: 0 | S5: 0 | V5: 0 | Y5: 0 | AB5: 0 | AE5: 0 | AH5: 0 | AK5: 0
A6: 5 | B6: RST_CNT_VDDRST | C6: EQ | F6: 1 | G6: 0 | J6: 0 | M6: 0 | P6: 0 | S6: 0 | V6: 0 | Y6: 0 | AB6: 0 | AE6: 0 | AH6: 0 | AK6: 0
A7: 6 | B7: RST_CNT_ExT_RST | C7: EQ | F7: 1 | G7: 0 | J7: 0 | M7: 0 | P7: 0 | S7: 0 | V7: 0 | Y7: 0 | AB7: 0 | AE7: 0 | AH7: 0 | AK7: 0
A8: 7 | B8: RST_CNT_WDRST | C8: EQ | F8: 1 | G8: 0 | J8: 0 | M8: 0 | P8: 0 | S8: 0 | V8: 0 | Y8: 0 | AB8: 0 | AE8: 0 | AH8: 0 | AK8: 0
A9: 8 | B9: RST_CNT_SWRST | C9: EQ | F9: 1 | G9: 0 | J9: 0 | M9: 0 | P9: 0 | S9: 0 | V9: 0 | Y9: 0 | AB9: 0 | AE9: 0 | AH9: 0 | AK9: 0
A10: 9 | B10: ERROR_CAUSE | C10: EQ | F10: 1 | G10: 0 | J10: 0 | M10: 0 | P10: 0 | S10: 0 | V10: 0 | Y10: 0 | AB10: 0 | AE10: 0 | AH10: 0 | AK10: 0
A11: 10 | B11: RST_ADDRESS | C11: EQ | F11: 1 | G11: 0 | J11: 0 | M11: 0 | P11: 0 | S11: 0 | V11: 0 | Y11: 0 | AB11: 0 | AE11: 0 | AH11: 0 | AK11: 0
A12: 11 | B12: RST_CNT_FAULTRST | C12: EQ | F12: 1 | G12: 0 | J12: 0 | M12: 0 | P12: 0 | S12: 0 | V12: 0 | Y12: 0 | AB12: 0 | AE12: 0 | AH12: 0 | AK12: 0
A13: 12 | B13: RST_CNT_CSVRST | C13: EQ | F13: 1 | G13: 0 | J13: 0 | M13: 0 | P13: 0 | S13: 0 | V13: 0 | Y13: 0 | AB13: 0 | AE13: 0 | AH13: 0 | AK13: 0
A14: 13 | B14: AN_STATUS | C14: EQ | F14: 1 | G14: 160 | J14: 160 | M14: 160 | P14: 160 | S14: 160 | V14: 160 | Y14: 160 | AB14: 160 | AE14: 160 | AH14: 160 | AK14: 160
A15: 14 | B15: Min_SIN/HALL0_A | C15: GELE | F15: 1 | G15: 2.5 | H15: =($G$15*5/Misc!$L$12)-0.1 -> 2.4 | I15: =($G$15*5/Misc!$L$12)+0.1 -> 2.6 | J15: 2.5 | K15: =($J$15*5/Misc!$L$13)-0.1 -> 2.4 | L15: =($J$15*5/Misc!$L$13)+0.1 -> 2.6 | M15: 2.5 | N15: =($M$15*5/Misc!$L$14)-0.1 -> 2.4 | O15: =($M$15*5/Misc!$L$14)+0.1 -> 2.6 | P15: 2.5 | Q15: =($P$15*5/Misc!$L$15)-0.1 -> 2.4 | R15: =($S$15*5/Misc!$L$15)+0.1 -> 2.6 | S15: 2.5 | T15: =($S$15*5/Misc!$L$16)-0.1 -> 2.4 | U15: =($S$15*5/Misc!$L$16)+0.1 -> 2.6 | V15: 2.5 | W15: =($V$15*5/Misc!$L$17)-0.1 -> 2.4 | X15: =($V$15*5/Misc!$L$17)+0.1 -> 2.6 | Y15: 2.5 | Z15: =($Y$15*5/Misc!$L$18)-0.1 -> 2.4 | AA15: =($Y$15*5/Misc!$L$18)+0.1 -> 2.6 | AB15: 2.48 | AC15: =($AB$15*5/Misc!$L$19)-0.1 -> 2.38 | AD15: =($AB$15*5/Misc!$L$19)+0.1 -> 2.58 | AE15: 2.5 | AF15: =($AE$15*5/Misc!$L$20)-0.1 -> 2.4 | AG15: =($AE$15*5/Misc!$L$20)+0.1 -> 2.6 | AH15: 2.5 | AI15: =($AH$15*5/Misc!$L$21)-0.1 -> 2.4 | AJ15: =($AH$15*5/Misc!$L$21)+0.1 -> 2.6 | AK15: 2.5 | AL15: =($AK$15*5/Misc!$L$22)-0.1 -> 2.4 | AM15: =($AK$15*5/Misc!$L$22)+0.1 -> 2.6
A16: 15 | B16: Max_SIN/HALL0_A | C16: GELE | F16: 1 | G16: 2.5 | H16: =($G$16*5/Misc!$L$12)-0.1 -> 2.4 | I16: =($G$16*5/Misc!$L$12)+0.1 -> 2.6 | J16: 2.5 | K16: =($J$16*5/Misc!$L$13)-0.1 -> 2.4 | L16: =($J$16*5/Misc!$L$13)+0.1 -> 2.6 | M16: 2.5 | N16: =($M$16*5/Misc!$L$14)-0.1 -> 2.4 | O16: =($M$16*5/Misc!$L$14)+0.1 -> 2.6 | P16: 2.5 | Q16: =($P$16*5/Misc!$L$15)-0.1 -> 2.4 | R16: =($S$16*5/Misc!$L$15)+0.1 -> 2.6 | S16: 2.5 | T16: =($S$16*5/Misc!$L$16)-0.1 -> 2.4 | U16: =($S$16*5/Misc!$L$16)+0.1 -> 2.6 | V16: 2.5 | W16: =($V$16*5/Misc!$L$17)-0.1 -> 2.4 | X16: =($V$16*5/Misc!$L$17)+0.1 -> 2.6 | Y16: 2.5 | Z16: =($Y$16*5/Misc!$L$18)-0.1 -> 2.4 | AA16: =($Y$16*5/Misc!$L$18)+0.1 -> 2.6 | AB16: 2.65 | AC16: =($AB$16*5/Misc!$L$19)-0.1 -> 2.55 | AD16: =($AB$16*5/Misc!$L$19)+0.1 -> 2.75 | AE16: 2.67 | AF16: =($AE$16*5/Misc!$L$20)-0.1 -> 2.57 | AG16: =($AE$16*5/Misc!$L$20)+0.1 -> 2.77 | AH16: 2.5 | AI16: =($AH$16*5/Misc!$L$21)-0.1 -> 2.4 | AJ16: =($AH$16*5/Misc!$L$21)+0.1 -> 2.6 | AK16: 2.5 | AL16: =($AK$16*5/Misc!$L$22)-0.1 -> 2.4 | AM16: =($AK$16*5/Misc!$L$22)+0.1 -> 2.6
A17: 16 | B17: TIMESTAMP_SIN/HALL0_A | F17: 0
A18: 17 | B18: Min_COSNEG/BRAKE_SW2_A | C18: GELE | F18: 1 | G18: 2.5 | H18: =($G$18*5*0.93058/Misc!$L$12)-0.015*3.4 -> 2.27545 | I18: =($G$18*5*1.072/Misc!$L$12)+0.015*3.4 -> 2.731 | J18: 2.5 | K18: =($J$18*5*0.93058/Misc!$L$13)-0.015*3.4 -> 2.27545 | L18: =($J$18*5*1.072/Misc!$L$13)+0.015*3.4 -> 2.731 | M18: 2.5 | N18: =($M$18*5*0.93058/Misc!$L$14)-0.015*3.4 -> 2.27545 | O18: =($M$18*5*1.072/Misc!$L$14)+0.015*3.4 -> 2.731 | P18: 2.5 | Q18: =($S$18*5*0.93058/Misc!$L$15)-0.015*3.4 -> 2.27545 | R18: =($S$18*5*1.072/Misc!$L$15)+0.015*3.4 -> 2.731 | S18: 2.5 | T18: =($S$18*5*0.93058/Misc!$L$16)-0.015*3.4 -> 2.27545 | U18: =($S$18*5*1.072/Misc!$L$16)+0.015*3.4 -> 2.731 | V18: 2.5 | W18: =($V$18*5*0.93058/Misc!$L$17)-0.015*3.4 -> 2.27545 | X18: =($V$18*5*1.072/Misc!$L$17)+0.015*3.4 -> 2.731 | Y18: 2.5 | Z18: =($Y$18*5*0.93058/Misc!$L$18)-0.015*3.4 -> 2.27545 | AA18: =($Y$18*5*1.072/Misc!$L$18)+0.015*3.4 -> 2.731 | AB18: 2.5 | AC18: =($AB$18*5*0.93058/Misc!$L$19)-0.015*3.4 -> 2.27545 | AD18: =($AB$18*5*1.072/Misc!$L$19)+0.015*3.4 -> 2.731 | AE18: 2.5 | AF18: =($AE$18*5*0.93058/Misc!$L$20)-0.015*3.4 -> 2.27545 | AG18: =($AE$18*5*1.072/Misc!$L$20)+0.015*3.4 -> 2.731 | AH18: 2.5 | AI18: =($AH$18*5*0.93058/Misc!$L$21)-0.015*3.4 -> 2.27545 | AJ18: =($AH$18*5*1.072/Misc!$L$21)+0.015*3.4 -> 2.731 | AK18: 2.5 | AL18: =($AK$18*5*0.93058/Misc!$L$22)-0.015*3.4 -> 2.27545 | AM18: =($AK$18*5*1.072/Misc!$L$22)+0.015*3.4 -> 2.731
A19: 18 | B19: Max_COSNEG/BRAKE_SW2_A | C19: GELE | F19: 1 | G19: 2.5 | H19: =($G$19*5*0.93058/Misc!$L$12)-0.015*3.4 -> 2.27545 | I19: =($G$19*5*1.072/Misc!$L$12)+0.015*3.4 -> 2.731 | J19: 2.5 | K19: =($J$19*5*0.93058/Misc!$L$13)-0.015*3.4 -> 2.27545 | L19: =($J$19*5*1.072/Misc!$L$13)+0.015*3.4 -> 2.731 | M19: 2.5 | N19: =($M$19*5*0.93058/Misc!$L$14)-0.015*3.4 -> 2.27545 | O19: =($M$19*5*1.072/Misc!$L$14)+0.015*3.4 -> 2.731 | P19: 2.5 | Q19: =($S$19*5*0.93058/Misc!$L$15)-0.015*3.4 -> 2.27545 | R19: =($S$19*5*1.072/Misc!$L$15)+0.015*3.4 -> 2.731 | S19: 2.5 | T19: =($S$19*5*0.93058/Misc!$L$16)-0.015*3.4 -> 2.27545 | U19: =($S$19*5*1.072/Misc!$L$16)+0.015*3.4 -> 2.731 | V19: 2.5 | W19: =($V$19*5*0.93058/Misc!$L$17)-0.015*3.4 -> 2.27545 | X19: =($V$19*5*1.072/Misc!$L$17)+0.015*3.4 -> 2.731 | Y19: 2.5 | Z19: =($Y$19*5*0.93058/Misc!$L$18)-0.015*3.4 -> 2.27545 | AA19: =($Y$19*5*1.072/Misc!$L$18)+0.015*3.4 -> 2.731 | AB19: 2.5 | AC19: =($AB$19*5*0.93058/Misc!$L$19)-0.015*3.4 -> 2.27545 | AD19: =($AB$19*5*1.072/Misc!$L$19)+0.015*3.4 -> 2.731 | AE19: 2.5 | AF19: =($AE$19*5*0.93058/Misc!$L$20)-0.015*3.4 -> 2.27545 | AG19: =($AE$19*5*1.072/Misc!$L$20)+0.015*3.4 -> 2.731 | AH19: 2.5 | AI19: =($AH$19*5*0.93058/Misc!$L$21)-0.015*3.4 -> 2.27545 | AJ19: =($AH$19*5*1.072/Misc!$L$21)+0.015*3.4 -> 2.731 | AK19: 2.5 | AL19: =($AK$19*5*0.93058/Misc!$L$22)-0.015*3.4 -> 2.27545 | AM19: =($AK$19*5*1.072/Misc!$L$22)+0.015*3.4 -> 2.731
A20: 19 | B20: TIMESTAMP_COSNEG/BRAKE_SW2_A | F20: 0
A21: 20 | B21: Min_TEMP_MOTOR_N_A | C21: GELE | F21: 1 | G21: 0.72 | H21: =(Misc!$J$28*14250/(14250+20140+(Misc!$J$6*222547/(Misc!$J$6+222547))))*(5/Misc!$L$12)-0.02 -> 0.6357386 | I21: =(Misc!$J$28*15750/(15750+19860+(Misc!$I$6*219453/(Misc!$I$6+219453))))*(5/Misc!$L$12)+0.02 -> 0.80722454 | J21: 0.72 | K21: =(Misc!$J$28*14250/(14250+20140+(Misc!$J$6*222547/(Misc!$J$6+222547))))*(5/Misc!$L$13)-0.02 -> 0.6357386 | L21: =(Misc!$J$28*15750/(15750+19860+(Misc!$I$6*219453/(Misc!$I$6+219453))))*(5/Misc!$L$13)+0.02 -> 0.80722454 | M21: 0.72 | N21: =(Misc!$J$28*14250/(14250+20140+(Misc!$J$6*222547/(Misc!$J$6+222547))))*(5/Misc!$L$14)-0.02 -> 0.6357386 | O21: =(Misc!$J$28*15750/(15750+19860+(Misc!$I$6*219453/(Misc!$I$6+219453))))*(5/Misc!$L$14)+0.02 -> 0.80722454 | P21: 0.72 | Q21: =(Misc!$J$28*14250/(14250+20140+(Misc!$J$6*222547/(Misc!$J$6+222547))))*(5/Misc!$L$15)-0.02 -> 0.6357386 | R21: =(Misc!$J$28*15750/(15750+19860+(Misc!$I$6*219453/(Misc!$I$6+219453))))*(5/Misc!$L$15)+0.02 -> 0.80722454 | S21: 0.72 | T21: =(Misc!$J$28*14250/(14250+20140+(Misc!$J$6*222547/(Misc!$J$6+222547))))*(5/Misc!$L$16)-0.02 -> 0.6357386 | U21: =(Misc!$J$28*15750/(15750+19860+(Misc!$I$6*219453/(Misc!$I$6+219453))))*(5/Misc!$L$16)+0.02 -> 0.80722454 | V21: 0.72 | W21: =(Misc!$J$28*14250/(14250+20140+(Misc!$J$6*222547/(Misc!$J$6+222547))))*(5/Misc!$L$17)-0.02 -> 0.6357386 | X21: =(Misc!$J$28*15750/(15750+19860+(Misc!$I$6*219453/(Misc!$I$6+219453))))*(5/Misc!$L$17)+0.02 -> 0.80722454 | Y21: 0.72 | Z21: =(Misc!$J$28*14250/(14250+20140+(Misc!$J$6*222547/(Misc!$J$6+222547))))*(5/Misc!$L$18)-0.02 -> 0.6357386 | AA21: =(Misc!$J$28*15750/(15750+19860+(Misc!$I$6*219453/(Misc!$I$6+219453))))*(5/Misc!$L$18)+0.02 -> 0.80722454 | AB21: 0.72 | AC21: =(Misc!$J$28*14250/(14250+20140+(Misc!$J$6*222547/(Misc!$J$6+222547))))*(5/Misc!$L$19)-0.02 -> 0.6357386 | AD21: =(Misc!$J$28*15750/(15750+19860+(Misc!$I$6*219453/(Misc!$I$6+219453))))*(5/Misc!$L$19)+0.02 -> 0.80722454 | AE21: 0.72 | AF21: =(Misc!$J$28*14250/(14250+20140+(Misc!$J$6*222547/(Misc!$J$6+222547))))*(5/Misc!$L$20)-0.02 -> 0.6357386 | AG21: =(Misc!$J$28*15750/(15750+19860+(Misc!$I$6*219453/(Misc!$I$6+219453))))*(5/Misc!$L$20)+0.02 -> 0.80722454 | AH21: 0.72 | AI21: =(Misc!$J$28*14250/(14250+20140+(Misc!$J$6*222547/(Misc!$J$6+222547))))*(5/Misc!$L$21)-0.02 -> 0.6357386 | AJ21: =(Misc!$J$28*15750/(15750+19860+(Misc!$I$6*219453/(Misc!$I$6+219453))))*(5/Misc!$L$21)+0.02 -> 0.80722454 | AK21: 1.6802333 | AL21: =(Misc!$J$28*14250/(14250+20140+(Misc!$J$6*222547/(Misc!$J$6+222547))))*(5/Misc!$L$22)-0.02 -> 0.6357386 | AM21: =(Misc!$J$28*15750/(15750+19860+(Misc!$I$6*219453/(Misc!$I$6+219453))))*(5/Misc!$L$22)+0.02 -> 0.80722454
A22: 21 | B22: Max_TEMP_MOTOR_N_A | C22: GELE | F22: 1 | G22: 0.72 | H22: =(Misc!$K$28*14250/(14250+20140+(Misc!$J$6*222547/(Misc!$J$6+222547))))*(5/Misc!$L$12)-0.02 -> 0.64233556 | I22: =(Misc!$K$28*15750/(15750+19860+(Misc!$I$6*219453/(Misc!$I$6+219453))))*(5/Misc!$L$12)+0.02 -> 0.81514431 | J22: 0.72 | K22: =(Misc!$K$28*14250/(14250+20140+(Misc!$J$6*222547/(Misc!$J$6+222547))))*(5/Misc!$L$13)-0.02 -> 0.64233556 | L22: =(Misc!$K$28*15750/(15750+19860+(Misc!$I$6*219453/(Misc!$I$6+219453))))*(5/Misc!$L$13)+0.02 -> 0.81514431 | M22: 0.72 | N22: =(Misc!$K$28*14250/(14250+20140+(Misc!$J$6*222547/(Misc!$J$6+222547))))*(5/Misc!$L$14)-0.02 -> 0.64233556 | O22: =(Misc!$K$28*15750/(15750+19860+(Misc!$I$6*219453/(Misc!$I$6+219453))))*(5/Misc!$L$14)+0.02 -> 0.81514431 | P22: 0.72 | Q22: =(Misc!$K$28*14250/(14250+20140+(Misc!$J$6*222547/(Misc!$J$6+222547))))*(5/Misc!$L$15)-0.02 -> 0.64233556 | R22: =(Misc!$K$28*15750/(15750+19860+(Misc!$I$6*219453/(Misc!$I$6+219453))))*(5/Misc!$L$15)+0.02 -> 0.81514431 | S22: 0.72 | T22: =(Misc!$K$28*14250/(14250+20140+(Misc!$J$6*222547/(Misc!$J$6+222547))))*(5/Misc!$L$16)-0.02 -> 0.64233556 | U22: =(Misc!$K$28*15750/(15750+19860+(Misc!$I$6*219453/(Misc!$I$6+219453))))*(5/Misc!$L$16)+0.02 -> 0.81514431 | V22: 0.72 | W22: =(Misc!$K$28*14250/(14250+20140+(Misc!$J$6*222547/(Misc!$J$6+222547))))*(5/Misc!$L$17)-0.02 -> 0.64233556 | X22: =(Misc!$K$28*15750/(15750+19860+(Misc!$I$6*219453/(Misc!$I$6+219453))))*(5/Misc!$L$17)+0.02 -> 0.81514431 | Y22: 0.72 | Z22: =(Misc!$K$28*14250/(14250+20140+(Misc!$J$6*222547/(Misc!$J$6+222547))))*(5/Misc!$L$18)-0.02 -> 0.64233556 | AA22: =(Misc!$K$28*15750/(15750+19860+(Misc!$I$6*219453/(Misc!$I$6+219453))))*(5/Misc!$L$18)+0.02 -> 0.81514431 | AB22: 0.72 | AC22: =(Misc!$K$28*14250/(14250+20140+(Misc!$J$6*222547/(Misc!$J$6+222547))))*(5/Misc!$L$19)-0.02 -> 0.64233556 | AD22: =(Misc!$K$28*15750/(15750+19860+(Misc!$I$6*219453/(Misc!$I$6+219453))))*(5/Misc!$L$19)+0.02 -> 0.81514431 | AE22: 0.72 | AF22: =(Misc!$K$28*14250/(14250+20140+(Misc!$J$6*222547/(Misc!$J$6+222547))))*(5/Misc!$L$20)-0.02 -> 0.64233556 | AG22: =(Misc!$K$28*15750/(15750+19860+(Misc!$I$6*219453/(Misc!$I$6+219453))))*(5/Misc!$L$20)+0.02 -> 0.81514431 | AH22: 0.72 | AI22: =(Misc!$K$28*14250/(14250+20140+(Misc!$J$6*222547/(Misc!$J$6+222547))))*(5/Misc!$L$21)-0.02 -> 0.64233556 | AJ22: =(Misc!$K$28*15750/(15750+19860+(Misc!$I$6*219453/(Misc!$I$6+219453))))*(5/Misc!$L$21)+0.02 -> 0.81514431 | AK22: 1.6825667 | AL22: =(Misc!$K$28*14250/(14250+20140+(Misc!$J$6*222547/(Misc!$J$6+222547))))*(5/Misc!$L$22)-0.02 -> 0.64233556 | AM22: =(Misc!$K$28*15750/(15750+19860+(Misc!$I$6*219453/(Misc!$I$6+219453))))*(5/Misc!$L$22)+0.02 -> 0.81514431
A23: 22 | B23: TIMESTAMP_TEMP_MOTOR_N_A | F23: 0
A24: 23 | B24: Min_TGS1_A | C24: GELE | F24: 1 | G24: 2.49 | H24: =($G$24*5/Misc!$L$12)-0.015 -> 2.475 | I24: =($G$24*5/Misc!$L$12)+0.015 -> 2.505 | J24: 2.49 | K24: =($J$24*5/Misc!$L$13)-0.015 -> 2.475 | L24: =($J$24*5/Misc!$L$13)+0.015 -> 2.505 | M24: 2.49 | N24: =($M$24*5/Misc!$L$14)-0.015 -> 2.475 | O24: =($M$24*5/Misc!$L$14)+0.015 -> 2.505 | P24: 2.49 | Q24: =($P$24*5/Misc!$L$15)-0.015 -> 2.475 | R24: =($P$24*5/Misc!$L$15)+0.015 -> 2.505 | S24: 2.49 | T24: =($S$24*5/Misc!$L$16)-0.015 -> 2.475 | U24: =($S$24*5/Misc!$L$16)+0.015 -> 2.505 | V24: 2.49 | W24: =($V$24*5/Misc!$L$17)-0.015 -> 2.475 | X24: =($V$24*5/Misc!$L$17)+0.015 -> 2.505 | Y24: 2.49 | Z24: =($Y$24*5/Misc!$L$18)-0.015 -> 2.475 | AA24: =($Y$24*5/Misc!$L$18)+0.015 -> 2.505 | AB24: 2.49 | AC24: =($AB$24*5/Misc!$L$19)-0.015 -> 2.475 | AD24: =($AB$24*5/Misc!$L$19)+0.015 -> 2.505 | AE24: 2.487 | AF24: =($AE$24*5/Misc!$L$20)-0.015 -> 2.472 | AG24: =($AE$24*5/Misc!$L$20)+0.015 -> 2.502 | AH24: 2.487 | AI24: =($AH$24*5/Misc!$L$21)-0.015 -> 2.472 | AJ24: =($AH$24*5/Misc!$L$21)+0.015 -> 2.502 | AK24: 2.487 | AL24: =($AK$24*5/Misc!$L$22)-0.015 -> 2.472 | AM24: =($AK$24*5/Misc!$L$22)+0.015 -> 2.502
A25: 24 | B25: Max_TGS1_A | C25: GELE | F25: 1 | G25: 2.495 | H25: =($G$25*5/Misc!$L$12)-0.015 -> 2.48 | I25: =($G$25*5/Misc!$L$12)+0.015 -> 2.51 | J25: 2.495 | K25: =($J$25*5/Misc!$L$13)-0.015 -> 2.48 | L25: =($J$25*5/Misc!$L$13)+0.015 -> 2.51 | M25: 2.495 | N25: =($M$25*5/Misc!$L$14)-0.015 -> 2.48 | O25: =($M$25*5/Misc!$L$14)+0.015 -> 2.51 | P25: 2.495 | Q25: =($P$25*5/Misc!$L$15)-0.015 -> 2.48 | R25: =($P$25*5/Misc!$L$15)+0.015 -> 2.51 | S25: 2.495 | T25: =($S$25*5/Misc!$L$16)-0.015 -> 2.48 | U25: =($S$25*5/Misc!$L$16)+0.015 -> 2.51 | V25: 2.495 | W25: =($V$25*5/Misc!$L$17)-0.015 -> 2.48 | X25: =($V$25*5/Misc!$L$17)+0.015 -> 2.51 | Y25: 2.495 | Z25: =($Y$25*5/Misc!$L$18)-0.015 -> 2.48 | AA25: =($Y$25*5/Misc!$L$18)+0.015 -> 2.51 | AB25: 2.495 | AC25: =($AB$25*5/Misc!$L$19)-0.015 -> 2.48 | AD25: =($AB$25*5/Misc!$L$19)+0.015 -> 2.51 | AE25: 2.49 | AF25: =($AE$25*5/Misc!$L$20)-0.015 -> 2.475 | AG25: =($AE$25*5/Misc!$L$20)+0.015 -> 2.505 | AH25: 2.49 | AI25: =($AH$25*5/Misc!$L$21)-0.015 -> 2.475 | AJ25: =($AH$25*5/Misc!$L$21)+0.015 -> 2.505 | AK25: 2.49 | AL25: =($AK$25*5/Misc!$L$22)-0.015 -> 2.475 | AM25: =($AK$25*5/Misc!$L$22)+0.015 -> 2.505
A26: 25 | B26: TIMESTAMP_TGS1_A | F26: 0
A27: 26 | B27: Min_V_5V_SENSOR1_A | C27: GELE | F27: 1 | G27: 4.995 | H27: =(Misc!$H$28)*(5*0.99/Misc!$L$12)-0.02*1.1 -> 4.8983 | I27: =(Misc!$H$28)*(5*1.008/Misc!$L$12)+0.02*1.1 -> 5.03176 | J27: 4.995 | K27: =(Misc!$H$28)*(5*0.99/Misc!$L$13)-0.02*1.1 -> 4.8983 | L27: =(Misc!$H$28)*(5*1.008/Misc!$L$13)+0.02*1.1 -> 5.03176 | M27: 4.995 | N27: =(Misc!$H$28)*(5*0.99/Misc!$L$14)-0.02*1.1 -> 4.8983 | O27: =(Misc!$H$28)*(5*1.008/Misc!$L$14)+0.02*1.1 -> 5.03176 | P27: 4.995 | Q27: =(Misc!$H$28)*(5*0.99/Misc!$L$15)-0.02*1.1 -> 4.8983 | R27: =(Misc!$H$28)*(5*1.008/Misc!$L$15)+0.02*1.1 -> 5.03176 | S27: 4.995 | T27: =(Misc!$H$28)*(5*0.99/Misc!$L$16)-0.02*1.1 -> 4.8983 | U27: =(Misc!$H$28)*(5*1.008/Misc!$L$16)+0.02*1.1 -> 5.03176 | V27: 4.995 | W27: =(Misc!$H$28)*(5*0.99/Misc!$L$17)-0.02*1.1 -> 4.8983 | X27: =(Misc!$H$28)*(5*1.008/Misc!$L$17)+0.02*1.1 -> 5.03176 | Y27: 4.995 | Z27: =(Misc!$H$28)*(5*0.99/Misc!$L$18)-0.02*1.1 -> 4.8983 | AA27: =(Misc!$H$28)*(5*1.008/Misc!$L$18)+0.02*1.1 -> 5.03176 | AB27: 5 | AC27: =(Misc!$H$28)*(5*0.99/Misc!$L$19)-0.02*1.1 -> 4.8983 | AD27: =(Misc!$H$28)*(5*1.008/Misc!$L$19)+0.02*1.1 -> 5.03176 | AE27: 4.995 | AF27: =(Misc!$H$28)*(5*0.99/Misc!$L$20)-0.02*1.1 -> 4.8983 | AG27: =(Misc!$H$28)*(5*1.008/Misc!$L$20)+0.02*1.1 -> 5.03176 | AH27: 4.995 | AI27: =(Misc!$H$28)*(5*0.99/Misc!$L$21)-0.02*1.1 -> 4.8983 | AJ27: =(Misc!$H$28)*(5*1.008/Misc!$L$21)+0.02*1.1 -> 5.03176 | AK27: 4.995 | AL27: =(Misc!$H$28)*(5*0.99/Misc!$L$22)-0.02*1.1 -> 4.8983 | AM27: =(Misc!$H$28)*(5*1.008/Misc!$L$22)+0.02*1.1 -> 5.03176
A28: 27 | B28: Max_V_5V_SENSOR1_A | C28: GELE | F28: 1 | G28: 5 | H28: =(Misc!$I$28)*(5*0.99/Misc!$L$12)-0.02*1.1 -> 4.9478 | I28: =(Misc!$I$28)*(5*1.008/Misc!$L$12)+0.02*1.1 -> 5.08216 | J28: 5 | K28: =(Misc!$I$28)*(5*0.99/Misc!$L$13)-0.02*1.1 -> 4.9478 | L28: =(Misc!$I$28)*(5*1.008/Misc!$L$13)+0.02*1.1 -> 5.08216 | M28: 5 | N28: =(Misc!$I$28)*(5*0.99/Misc!$L$14)-0.02*1.1 -> 4.9478 | O28: =(Misc!$I$28)*(5*1.008/Misc!$L$14)+0.02*1.1 -> 5.08216 | P28: 5 | Q28: =(Misc!$I$28)*(5*0.99/Misc!$L$15)-0.02*1.1 -> 4.9478 | R28: =(Misc!$I$28)*(5*1.008/Misc!$L$15)+0.02*1.1 -> 5.08216 | S28: 5 | T28: =(Misc!$I$28)*(5*0.99/Misc!$L$16)-0.02*1.1 -> 4.9478 | U28: =(Misc!$I$28)*(5*1.008/Misc!$L$16)+0.02*1.1 -> 5.08216 | V28: 5 | W28: =(Misc!$I$28)*(5*0.99/Misc!$L$17)-0.02*1.1 -> 4.9478 | X28: =(Misc!$I$28)*(5*1.008/Misc!$L$17)+0.02*1.1 -> 5.08216 | Y28: 5 | Z28: =(Misc!$I$28)*(5*0.99/Misc!$L$18)-0.02*1.1 -> 4.9478 | AA28: =(Misc!$I$28)*(5*1.008/Misc!$L$18)+0.02*1.1 -> 5.08216 | AB28: 5 | AC28: =(Misc!$I$28)*(5*0.99/Misc!$L$19)-0.02*1.1 -> 4.9478 | AD28: =(Misc!$I$28)*(5*1.008/Misc!$L$19)+0.02*1.1 -> 5.08216 | AE28: 5 | AF28: =(Misc!$I$28)*(5*0.99/Misc!$L$20)-0.02*1.1 -> 4.9478 | AG28: =(Misc!$I$28)*(5*1.008/Misc!$L$20)+0.02*1.1 -> 5.08216 | AH28: 5 | AI28: =(Misc!$I$28)*(5*0.99/Misc!$L$21)-0.02*1.1 -> 4.9478 | AJ28: =(Misc!$I$28)*(5*1.008/Misc!$L$21)+0.02*1.1 -> 5.08216 | AK28: 5 | AL28: =(Misc!$I$28)*(5*0.99/Misc!$L$22)-0.02*1.1 -> 4.9478 | AM28: =(Misc!$I$28)*(5*1.008/Misc!$L$22)+0.02*1.1 -> 5.08216
A29: 28 | B29: TIMESTAMP_V_5V_SENSOR1_A | F29: 0
A30: 29 | B30: Min_SIDESTAND_SW_A | C30: GELE | F30: 1 | G30: 2.5 | H30: =($G$30*5*0.93058/Misc!$L$12)-0.02*3.4 -> 2.25845 | I30: =($G$30*5*1.072/Misc!$L$12)+0.02*3.4 -> 2.748 | J30: 2.5 | K30: =($J$30*5*0.93058/Misc!$L$13)-0.02*3.4 -> 2.25845 | L30: =($J$30*5*1.072/Misc!$L$13)+0.02*3.4 -> 2.748 | M30: 2.5 | N30: =($M$30*5*0.93058/Misc!$L$14)-0.02*3.4 -> 2.25845 | O30: =($M$30*5*1.072/Misc!$L$14)+0.02*3.4 -> 2.748 | P30: 2.5 | Q30: =($P$30*5*0.93058/Misc!$L$15)-0.02*3.4 -> 2.25845 | R30: =($P$30*5*1.072/Misc!$L$15)+0.02*3.4 -> 2.748 | S30: 2.5 | T30: =($S$30*5*0.93058/Misc!$L$16)-0.02*3.4 -> 2.25845 | U30: =($S$30*5*1.072/Misc!$L$16)+0.02*3.4 -> 2.748 | V30: 2.5 | W30: =($V$30*5*0.93058/Misc!$L$17)-0.02*3.4 -> 2.25845 | X30: =($V$30*5*1.072/Misc!$L$17)+0.02*3.4 -> 2.748 | Y30: 2.5 | Z30: =($Y$30*5*0.93058/Misc!$L$18)-0.02*3.4 -> 2.25845 | AA30: =($Y$30*5*1.072/Misc!$L$18)+0.02*3.4 -> 2.748 | AB30: 2.5 | AC30: =($AB$30*5*0.93058/Misc!$L$19)-0.02*3.4 -> 2.25845 | AD30: =($AB$30*5*1.072/Misc!$L$19)+0.02*3.4 -> 2.748 | AE30: 2.5 | AF30: =($AE$30*5*0.93058/Misc!$L$20)-0.02*3.4 -> 2.25845 | AG30: =($AE$30*5*1.072/Misc!$L$20)+0.02*3.4 -> 2.748 | AH30: 2.5 | AI30: =($AH$30*5*0.93058/Misc!$L$21)-0.02*3.4 -> 2.25845 | AJ30: =($AH$30*5*1.072/Misc!$L$21)+0.02*3.4 -> 2.748 | AK30: 2.5 | AL30: =($AK$30*5*0.93058/Misc!$L$22)-0.02*3.4 -> 2.25845 | AM30: =($AK$30*5*1.072/Misc!$L$22)+0.02*3.4 -> 2.748
A31: 30 | B31: Max_SIDESTAND_SW_A | C31: GELE | F31: 1 | G31: 2.5 | H31: =($G$31*5*0.93058/Misc!$L$12)-0.02*3.4 -> 2.25845 | I31: =($G$31*5*1.072/Misc!$L$12)+0.02*3.4 -> 2.748 | J31: 2.5 | K31: =($J$31*5*0.93058/Misc!$L$13)-0.02*3.4 -> 2.25845 | L31: =($J$31*5*1.072/Misc!$L$13)+0.02*3.4 -> 2.748 | M31: 2.5 | N31: =($M$31*5*0.93058/Misc!$L$14)-0.02*3.4 -> 2.25845 | O31: =($M$31*5*1.072/Misc!$L$14)+0.02*3.4 -> 2.748 | P31: 2.5 | Q31: =($P$31*5*0.93058/Misc!$L$15)-0.02*3.4 -> 2.25845 | R31: =($P$31*5*1.072/Misc!$L$15)+0.02*3.4 -> 2.748 | S31: 2.5 | T31: =($S$31*5*0.93058/Misc!$L$16)-0.02*3.4 -> 2.25845 | U31: =($S$31*5*1.072/Misc!$L$16)+0.02*3.4 -> 2.748 | V31: 2.5 | W31: =($V$31*5*0.93058/Misc!$L$17)-0.02*3.4 -> 2.25845 | X31: =($V$31*5*1.072/Misc!$L$17)+0.02*3.4 -> 2.748 | Y31: 2.5 | Z31: =($Y$31*5*0.93058/Misc!$L$18)-0.02*3.4 -> 2.25845 | AA31: =($Y$31*5*1.072/Misc!$L$18)+0.02*3.4 -> 2.748 | AB31: 2.5 | AC31: =($AB$31*5*0.93058/Misc!$L$19)-0.02*3.4 -> 2.25845 | AD31: =($AB$31*5*1.072/Misc!$L$19)+0.02*3.4 -> 2.748 | AE31: 2.5 | AF31: =($AE$31*5*0.93058/Misc!$L$20)-0.02*3.4 -> 2.25845 | AG31: =($AE$31*5*1.072/Misc!$L$20)+0.02*3.4 -> 2.748 | AH31: 2.5 | AI31: =($AH$31*5*0.93058/Misc!$L$21)-0.02*3.4 -> 2.25845 | AJ31: =($AH$31*5*1.072/Misc!$L$21)+0.02*3.4 -> 2.748 | AK31: 2.5 | AL31: =($AK$31*5*0.93058/Misc!$L$22)-0.02*3.4 -> 2.25845 | AM31: =($AK$31*5*1.072/Misc!$L$22)+0.02*3.4 -> 2.748
A32: 31 | B32: TIMESTAMP_SIDESTAND_SW_A | F32: 0
A33: 32 | B33: Min_MODE+_A | C33: GELE | F33: 1 | G33: 2.5 | H33: =($G$33*5*0.93058/Misc!$L$12)-0.02*3.4 -> 2.25845 | I33: =($G$33*5*1.072/Misc!$L$12)+0.02*3.4 -> 2.748 | J33: 2.5 | K33: =($J$33*5*0.93058/Misc!$L$13)-0.02*3.4 -> 2.25845 | L33: =($J$33*5*1.072/Misc!$L$13)+0.02*3.4 -> 2.748 | M33: 2.5 | N33: =($M$33*5*0.93058/Misc!$L$14)-0.02*3.4 -> 2.25845 | O33: =($M$33*5*1.072/Misc!$L$14)+0.02*3.4 -> 2.748 | P33: 2.5 | Q33: =($P$33*5*0.93058/Misc!$L$15)-0.02*3.4 -> 2.25845 | R33: =($P$33*5*1.072/Misc!$L$15)+0.02*3.4 -> 2.748 | S33: 2.5 | T33: =($S$33*5*0.93058/Misc!$L$16)-0.02*3.4 -> 2.25845 | U33: =($S$33*5*1.072/Misc!$L$16)+0.02*3.4 -> 2.748 | V33: 2.5 | W33: =($V$33*5*0.93058/Misc!$L$17)-0.02*3.4 -> 2.25845 | X33: =($V$33*5*1.072/Misc!$L$17)+0.02*3.4 -> 2.748 | Y33: 2.5 | Z33: =($Y$33*5*0.93058/Misc!$L$18)-0.02*3.4 -> 2.25845 | AA33: =($Y$33*5*1.072/Misc!$L$18)+0.02*3.4 -> 2.748 | AB33: 2.5 | AC33: =($AB$33*5*0.93058/Misc!$L$19)-0.02*3.4 -> 2.25845 | AD33: =($AB$33*5*1.072/Misc!$L$19)+0.02*3.4 -> 2.748 | AE33: 2.5 | AF33: =($AE$33*5*0.93058/Misc!$L$20)-0.02*3.4 -> 2.25845 | AG33: =($AE$33*5*1.072/Misc!$L$20)+0.02*3.4 -> 2.748 | AH33: 2.5 | AI33: =($AH$33*5*0.93058/Misc!$L$21)-0.02*3.4 -> 2.25845 | AJ33: =($AH$33*5*1.072/Misc!$L$21)+0.02*3.4 -> 2.748 | AK33: 2.5 | AL33: =($AK$33*5*0.93058/Misc!$L$22)-0.02*3.4 -> 2.25845 | AM33: =($AK$33*5*1.072/Misc!$L$22)+0.02*3.4 -> 2.748
A34: 33 | B34: Max_MODE+_A | C34: GELE | F34: 1 | G34: 2.5 | H34: =($G$34*5*0.93058/Misc!$L$12)-0.02*3.4 -> 2.25845 | I34: =($G$34*5*1.072/Misc!$L$12)+0.02*3.4 -> 2.748 | J34: 2.5 | K34: =($J$34*5*0.93058/Misc!$L$13)-0.02*3.4 -> 2.25845 | L34: =($J$34*5*1.072/Misc!$L$13)+0.02*3.4 -> 2.748 | M34: 2.5 | N34: =($M$34*5*0.93058/Misc!$L$14)-0.02*3.4 -> 2.25845 | O34: =($M$34*5*1.072/Misc!$L$14)+0.02*3.4 -> 2.748 | P34: 2.5 | Q34: =($P$34*5*0.93058/Misc!$L$15)-0.02*3.4 -> 2.25845 | R34: =($P$34*5*1.072/Misc!$L$15)+0.02*3.4 -> 2.748 | S34: 2.5 | T34: =($S$34*5*0.93058/Misc!$L$16)-0.02*3.4 -> 2.25845 | U34: =($S$34*5*1.072/Misc!$L$16)+0.02*3.4 -> 2.748 | V34: 2.5 | W34: =($V$34*5*0.93058/Misc!$L$17)-0.02*3.4 -> 2.25845 | X34: =($V$34*5*1.072/Misc!$L$17)+0.02*3.4 -> 2.748 | Y34: 2.5 | Z34: =($Y$34*5*0.93058/Misc!$L$18)-0.02*3.4 -> 2.25845 | AA34: =($Y$34*5*1.072/Misc!$L$18)+0.02*3.4 -> 2.748 | AB34: 2.5 | AC34: =($AB$34*5*0.93058/Misc!$L$19)-0.02*3.4 -> 2.25845 | AD34: =($AB$34*5*1.072/Misc!$L$19)+0.02*3.4 -> 2.748 | AE34: 2.5 | AF34: =($AE$34*5*0.93058/Misc!$L$20)-0.02*3.4 -> 2.25845 | AG34: =($AE$34*5*1.072/Misc!$L$20)+0.02*3.4 -> 2.748 | AH34: 2.5 | AI34: =($AH$34*5*0.93058/Misc!$L$21)-0.02*3.4 -> 2.25845 | AJ34: =($AH$34*5*1.072/Misc!$L$21)+0.02*3.4 -> 2.748 | AK34: 2.5 | AL34: =($AK$34*5*0.93058/Misc!$L$22)-0.02*3.4 -> 2.25845 | AM34: =($AK$34*5*1.072/Misc!$L$22)+0.02*3.4 -> 2.748
A35: 34 | B35: TIMESTAMP_MODE+_A | F35: 0
A36: 35 | B36: Min_TEMP_INVERTER_A | C36: GELE | F36: 1 | H36: =Misc!$J$12*1.05 -> 0 | I36: =Misc!$K$12*1.05 -> 120.75 | K36: =Misc!$J$13*1.05 -> 0 | L36: =Misc!$K$13*1.05 -> 120.75 | N36: =Misc!$J$14*1.05 -> 0 | O36: =Misc!$K$14*1.05 -> 120.75 | Q36: =Misc!$J$15*1.05 -> 0 | R36: =Misc!$K$15*1.05 -> 120.75 | T36: =Misc!$J$16*1.05 -> 0 | U36: =Misc!$K$16*1.05 -> 120.75 | W36: =Misc!$J$17*1.05 -> 0 | X36: =Misc!$K$17*1.05 -> 120.75 | Z36: =Misc!$J$18*1.05 -> 0 | AA36: =Misc!$K$18*1.05 -> 120.75 | AC36: =Misc!$J$19*1.05 -> -21 | AD36: =Misc!$K$19*1.05 -> 120.75 | AF36: =Misc!$J$20*1.05 -> -21 | AG36: =Misc!$K$20*1.05 -> 120.75 | AI36: =Misc!$J$21*1.05 -> 0 | AJ36: =Misc!$K$21*1.05 -> 120.75 | AL36: =Misc!$J$22*1.05 -> 0 | AM36: =Misc!$K$22*1.05 -> 120.75
A37: 36 | B37: Max_TEMP_INVERTER_A | C37: GELE | F37: 1 | H37: =Misc!$J$12*1.05 -> 0 | I37: =Misc!$K$12*1.05 -> 120.75 | K37: =Misc!$J$13*1.05 -> 0 | L37: =Misc!$K$13*1.05 -> 120.75 | N37: =Misc!$J$14*1.05 -> 0 | O37: =Misc!$K$14*1.05 -> 120.75 | Q37: =Misc!$J$15*1.05 -> 0 | R37: =Misc!$K$15*1.05 -> 120.75 | T37: =Misc!$J$16*1.05 -> 0 | U37: =Misc!$K$16*1.05 -> 120.75 | W37: =Misc!$J$17*1.05 -> 0 | X37: =Misc!$K$17*1.05 -> 120.75 | Z37: =Misc!$J$18*1.05 -> 0 | AA37: =Misc!$K$18*1.05 -> 120.75 | AC37: =Misc!$J$19*1.05 -> -21 | AD37: =Misc!$K$19*1.05 -> 120.75 | AF37: =Misc!$J$20*1.05 -> -21 | AG37: =Misc!$K$20*1.05 -> 120.75 | AI37: =Misc!$J$21*1.05 -> 0 | AJ37: =Misc!$K$21*1.05 -> 120.75 | AL37: =Misc!$J$22*1.05 -> 0 | AM37: =Misc!$K$22*1.05 -> 120.75
A38: 37 | B38: TIMESTAMP_TEMP_INVERTER_A | F38: 0
A39: 38 | B39: Min_RUN_SW_A | C39: GELE | F39: 1 | G39: 2.5 | H39: =($G$39*5*0.93058/Misc!$L$12)-0.02*3.4 -> 2.25845 | I39: =($G$39*5*1.072/Misc!$L$12)+0.02*3.4 -> 2.748 | J39: 2.5 | K39: =($J$39*5*0.93058/Misc!$L$13)-0.02*3.4 -> 2.25845 | L39: =($J$39*5*1.072/Misc!$L$13)+0.02*3.4 -> 2.748 | M39: 2.5 | N39: =($M$39*5*0.93058/Misc!$L$14)-0.02*3.4 -> 2.25845 | O39: =($M$39*5*1.072/Misc!$L$14)+0.02*3.4 -> 2.748 | P39: 2.5 | Q39: =($P$39*5*0.93058/Misc!$L$15)-0.02*3.4 -> 2.25845 | R39: =($P$39*5*1.072/Misc!$L$15)+0.02*3.4 -> 2.748 | S39: 2.5 | T39: =($S$39*5*0.93058/Misc!$L$16)-0.02*3.4 -> 2.25845 | U39: =($S$39*5*1.072/Misc!$L$16)+0.02*3.4 -> 2.748 | V39: 2.5 | W39: =($V$39*5*0.93058/Misc!$L$17)-0.02*3.4 -> 2.25845 | X39: =($V$39*5*1.072/Misc!$L$17)+0.02*3.4 -> 2.748 | Y39: 2.5 | Z39: =($Y$39*5*0.93058/Misc!$L$18)-0.02*3.4 -> 2.25845 | AA39: =($Y$39*5*1.072/Misc!$L$18)+0.02*3.4 -> 2.748 | AB39: 2.5 | AC39: =($AB$39*5*0.93058/Misc!$L$19)-0.02*3.4 -> 2.25845 | AD39: =($AB$39*5*1.072/Misc!$L$19)+0.02*3.4 -> 2.748 | AE39: 2.5 | AF39: =($AE$39*5*0.93058/Misc!$L$20)-0.02*3.4 -> 2.25845 | AG39: =($AE$39*5*1.072/Misc!$L$20)+0.02*3.4 -> 2.748 | AH39: 2.5 | AI39: =($AH$39*5*0.93058/Misc!$L$21)-0.02*3.4 -> 2.25845 | AJ39: =($AH$39*5*1.072/Misc!$L$21)+0.02*3.4 -> 2.748 | AK39: 2.5 | AL39: =($AK$39*5*0.93058/Misc!$L$22)-0.02*3.4 -> 2.25845 | AM39: =($AK$39*5*1.072/Misc!$L$22)+0.02*3.4 -> 2.748
A40: 39 | B40: Max_RUN_SW_A | C40: GELE | F40: 1 | G40: 2.5 | H40: =($G$40*5*0.93058/Misc!$L$12)-0.02*3.4 -> 2.25845 | I40: =($G$40*5*1.072/Misc!$L$12)+0.02*3.4 -> 2.748 | J40: 2.5 | K40: =($J$40*5*0.93058/Misc!$L$13)-0.02*3.4 -> 2.25845 | L40: =($J$40*5*1.072/Misc!$L$13)+0.02*3.4 -> 2.748 | M40: 2.5 | N40: =($M$40*5*0.93058/Misc!$L$14)-0.02*3.4 -> 2.25845 | O40: =($M$40*5*1.072/Misc!$L$14)+0.02*3.4 -> 2.748 | P40: 2.5 | Q40: =($P$40*5*0.93058/Misc!$L$15)-0.02*3.4 -> 2.25845 | R40: =($P$40*5*1.072/Misc!$L$15)+0.02*3.4 -> 2.748 | S40: 2.5 | T40: =($S$40*5*0.93058/Misc!$L$16)-0.02*3.4 -> 2.25845 | U40: =($S$40*5*1.072/Misc!$L$16)+0.02*3.4 -> 2.748 | V40: 2.5 | W40: =($V$40*5*0.93058/Misc!$L$17)-0.02*3.4 -> 2.25845 | X40: =($V$40*5*1.072/Misc!$L$17)+0.02*3.4 -> 2.748 | Y40: 2.5 | Z40: =($Y$40*5*0.93058/Misc!$L$18)-0.02*3.4 -> 2.25845 | AA40: =($Y$40*5*1.072/Misc!$L$18)+0.02*3.4 -> 2.748 | AB40: 2.5 | AC40: =($AB$40*5*0.93058/Misc!$L$19)-0.02*3.4 -> 2.25845 | AD40: =($AB$40*5*1.072/Misc!$L$19)+0.02*3.4 -> 2.748 | AE40: 2.5 | AF40: =($AE$40*5*0.93058/Misc!$L$20)-0.02*3.4 -> 2.25845 | AG40: =($AE$40*5*1.072/Misc!$L$20)+0.02*3.4 -> 2.748 | AH40: 2.5 | AI40: =($AH$40*5*0.93058/Misc!$L$21)-0.02*3.4 -> 2.25845 | AJ40: =($AH$40*5*1.072/Misc!$L$21)+0.02*3.4 -> 2.748 | AK40: 2.5 | AL40: =($AK$40*5*0.93058/Misc!$L$22)-0.02*3.4 -> 2.25845 | AM40: =($AK$40*5*1.072/Misc!$L$22)+0.02*3.4 -> 2.748
...

Sheet Misc
B4: Comparision Type | I4: tolerance | J4: tolerance
B5: EQ | C5: Equal to (==) | G5: CSA gain min | H5: CSA gain max | I5: Temp_motor min R | J5: Temp_motor max R
B6: NE | C6: Not equal to (!=) | E6: CSA gain | F6: 30 | G6: =IF(F6=10,9.7,0)+IF(F6=20,19.4,0)+IF(F6=30,29.1,0)+IF(F6=40,38.8,0) -> 29.1 | H6: =IF(F6=10,10.3,0)+IF(F6=20,20.6,0)+IF(F6=30,30.9,0)+IF(F6=40,41.2,0) -> 30.9 | I6: =L28*0.9 -> 90000 | J6: =L28*1.1 -> 110000
B7: GELE | C7: Greater than or equal to AND Less than or equal to (>= <=)
B8: EQT | C8: Equal to Threshold( == +/-), Percentage % of Nominal Value
E9: Variables (Dependent on Modes)
E10: Modes | F10: Min Current (A) | G10: Max current (A) | H10: Min DCLink voltage (V) | I10: Max DCLink voltage (V) | J10: Min PCB temperature (°C) | K10: Max PCB temperature (°C) | L10: V_5V_REF (mean) | M10: Min Micro temperature (°C) | N10: Max Micro temperature (°C)
E11: Mode 0 | F11: 0 | G11: 0 | H11: 48 | I11: 48 | J11: 0 | K11: 115 | L11: 5 | M11: 0 | N11: 110
E12: Mode1 | F12: 0 | G12: 0 | H12: 48 | I12: 48 | J12: 0 | K12: 115 | L12: 5 | M12: 0 | N12: 110
E13: Mode 2 | F13: 18 | G13: 45 | H13: 48 | I13: 48 | J13: 0 | K13: 115 | L13: 5 | M13: 0 | N13: 110
E14: Mode 3 | F14: 25 | G14: 65 | H14: 48 | I14: 48 | J14: 0 | K14: 115 | L14: 5 | M14: 0 | N14: 110
E15: Mode 4 | F15: 75 | G15: 95 | H15: 48 | I15: 48 | J15: 0 | K15: 115 | L15: 5 | M15: 0 | N15: 110
E16: Mode 5 | F16: 95 | G16: 115 | H16: 48 | I16: 48 | J16: 0 | K16: 115 | L16: 5 | M16: 0 | N16: 110
E17: Mode 6 | F17: 32.5 | G17: 65 | H17: 48 | I17: 48 | J17: 0 | K17: 115 | L17: 5 | M17: 0 | N17: 110
E18: Mode 7 | F18: 47.5 | G18: 95 | H18: 48 | I18: 48 | J18: 0 | K18: 115 | L18: 5 | M18: 0 | N18: 110
E19: Mode 8 | F19: 120 | G19: 133 | H19: 48 | I19: 48 | J19: -20 | K19: 115 | L19: 5 | M19: -20 | N19: 110
E20: Mode 9 | F20: 80 | G20: 80 | H20: 48 | I20: 48 | J20: -20 | K20: 115 | L20: 5 | M20: -20 | N20: 110
E21: Mode 10 | F21: 120 | G21: 120 | H21: 48 | I21: 48 | J21: 0 | K21: 115 | L21: 5 | M21: 0 | N21: 110
E22: Mode 11 | F22: 133 | G22: 133 | H22: 48 | I22: 48 | J22: 0 | K22: 115 | L22: 5 | M22: 0 | N22: 110
E23: Mode 12 | F23: 1 | G23: 1 | H23: 48 | I23: 48 | J23: 0 | K23: 115 | L23: 5 | M23: 0 | N23: 110
E26: Common for Modes (Mode 0 to Mode 12)
E27: Mode 0 to Mode 12 | G27: CSA Offset | H27: V_5V_Sensor1 min | I27: V_5V_Sensor1 max | J27: V_5V_Sensor2 min | K27: V_5V_Sensor2 max | L27: Temp_motor external resistor | M27: V_5V min | N27: V_5V max
G28: 2.5 | H28: 4.97 | I28: 5.02 | J28: 4.97 | K28: 5.02 | L28: 100000 | M28: 4.94 | N28: 5
